<?xml version='1.0'?>
<sdf version='1.6'>
  <model name='test1'>
    <model name='my_robot'>
      <static>0</static>
      <link name='chassis'>
        <pose frame=''>0 0 0.1 0 -0 0</pose>
        <inertial>
          <mass>10</mass>
          <pose frame=''>0 0 0.1 0 -0 0</pose>
          <inertia>
            <ixx>0.5</ixx>
            <iyy>1</iyy>
            <izz>0.1</izz>
            <ixy>0</ixy>
            <ixz>0</ixz>
            <iyz>0</iyz>
          </inertia>
        </inertial>
        <collision name='collision'>
          <geometry>
            <box>
              <size>0.4 0.2 0.1</size>
            </box>
          </geometry>
        </collision>
        <visual name='visual'>
          <pose frame=''>0 0 0.05 0 -0 0</pose>
          <geometry>
            <mesh>
              <uri>model://pioneer2dx/meshes/chassis.dae</uri>
              <scale>0.9 0.5 0.5</scale>
            </mesh>
          </geometry>
        </visual>
        <collision name='caster_collision'>
          <pose frame=''>-0.15 0 -0.05 0 -0 0</pose>
          <geometry>
            <sphere>
              <radius>0.05</radius>
            </sphere>
          </geometry>
          <surface>
            <friction>
              <ode>
                <mu>0</mu>
                <mu2>0</mu2>
                <slip1>1</slip1>
                <slip2>1</slip2>
              </ode>
            </friction>
          </surface>
        </collision>
        <visual name='caster_visual'>
          <pose frame=''>-0.15 0 -0.05 0 -0 0</pose>
          <geometry>
            <sphere>
              <radius>0.05</radius>
            </sphere>
          </geometry>
        </visual>
      </link>
      <link name='left_wheel'>
        <pose frame=''>0.1 0.13 0.1 -0 1.5707 1.5707</pose>
        <collision name='collision'>
          <geometry>
            <cylinder>
              <radius>0.1</radius>
              <length>0.05</length>
            </cylinder>
          </geometry>
        </collision>
        <visual name='visual'>
          <geometry>
            <cylinder>
              <radius>0.1</radius>
              <length>0.05</length>
            </cylinder>
          </geometry>
        </visual>
      </link>
      <link name='right_wheel'>
        <pose frame=''>0.1 -0.13 0.1 -0 1.5707 1.5707</pose>
        <collision name='collision'>
          <geometry>
            <cylinder>
              <radius>0.1</radius>
              <length>0.05</length>
            </cylinder>
          </geometry>
        </collision>
        <visual name='visual'>
          <geometry>
            <cylinder>
              <radius>0.1</radius>
              <length>0.05</length>
            </cylinder>
          </geometry>
        </visual>
      </link>
      <joint name='left_wheel_hinge' type='revolute'>
        <pose frame=''>0 0 -0.03 0 -0 0</pose>
        <child>left_wheel</child>
        <parent>chassis</parent>
        <axis>
          <xyz>0 1 0</xyz>
          <use_parent_model_frame>1</use_parent_model_frame>
          <limit>
            <lower>-1e+16</lower>
            <upper>1e+16</upper>
          </limit>
        </axis>
      </joint>
      <joint name='right_wheel_hinge' type='revolute'>
        <pose frame=''>0 0 0.03 0 -0 0</pose>
        <child>right_wheel</child>
        <parent>chassis</parent>
        <axis>
          <xyz>0 1 0</xyz>
          <use_parent_model_frame>1</use_parent_model_frame>
          <limit>
            <lower>-1e+16</lower>
            <upper>1e+16</upper>
          </limit>
        </axis>
      </joint>
      <plugin name='differential_drive_controller' filename='libgazebo_ros_diff_drive.so'>
        <alwaysOn>true</alwaysOn>
        <updateRate>20</updateRate>
        <leftJoint>left_wheel_hinge</leftJoint>
        <rightJoint>right_wheel_hinge</rightJoint>
        <wheelSeparation>0.4</wheelSeparation>
        <wheelDiameter>0.1</wheelDiameter>
        <torque>20</torque>
        <commandTopic>cmd_vel</commandTopic>
        <odometryTopic>odom</odometryTopic>
        <odometryFrame>odom</odometryFrame>
        <robotBaseFrame>base_footprint</robotBaseFrame>
      </plugin>
      <pose frame=''>0 0 0 0 -0 0</pose>
    </model>
    <static>0</static>
    <allow_auto_disable>1</allow_auto_disable>
  </model>
</sdf>
